Workbook

Sheet Kaarten review
A1: ID | B1: Module | C1: Bron | D1: Type | E1: Vraag | F1: Antwoord | G1: Citaat | H1: Context | I1: Vindplaats | J1: Oordeel | K1: Opmerking
A2: card_001 | B2: 01 | C2: Groningenveld (HR 19 juli 2019) | D2: arrest | E2: Kan een benadeelde zijn vordering uit hoofde van mijnbouwschade óók op art. 6:162 BW baseren, terwijl er een risicoaansprakelijkheid op grond van art. 6:177 BW beschikbaar is? | F2: Ja. Ondanks de ruime toerekening die plaatsvindt bij aansprakelijkheid op grond van art. 6:177 BW, kan de vordering (ook) op grond van art. 6:162 BW worden beoordeeld wanneer dat voor de benadeelde tot een gunstiger resultaat leidt. De twee grondslagen sluiten elkaar niet uit. | G2: Ondanks de ruime toerekening die plaatsvindt bij aansprakelijkheid op grond van art. 6:177 BW, kunnen zich gevallen voordoen waarin het voor de benadeelde tot een gunstiger resultaat leidt als zijn vordering niet (of niet alleen) op grond van art. 6:177 BW, maar (ook) op grond van art. 6:162 BW wordt beoordeeld. | H2: Kern van het Groningenveld-arrest: samenloop tussen risico- en schuldaansprakelijkheid bij aardbevingsschade door gaswinning. | I2: HR 19 juli 2019, ECLI:NL:HR:2019:1278, NJ 2020/391 (Groningenveld)
A3: card_002 | B3: 01 | C3: Groningenveld (HR 19 juli 2019) | D3: arrest | E3: Moet EBN B.V. naast NAM worden aangemerkt als exploitant in de zin van art. 6:177 lid 2 BW? | F3: Ja. EBN, waarvan de Staat enig aandeelhouder is, moet naast NAM als exploitant in de zin van art. 6:177 lid 2 BW worden aangemerkt omdat EBN via de Maatschap Groningen het economische belang bij de gaswinning deelt. | G3: EBN, waarvan de Staat enig aandeelhouder is, moet in het onderhavige geval — naast NAM — als exploitant in de zin van art. 6:177 lid 2 BW worden aangemerkt. | H3: Uitbreiding van het exploitantbegrip: ook de medebelanghebbende via een maatschapsconstructie valt eronder. | I3: HR 19 juli 2019, ECLI:NL:HR:2019:1278, NJ 2020/391 (Groningenveld)
A4: card_003 | B4: 01 | C4: Groningenveld (HR 19 juli 2019) | D4: arrest | E4: Hoe kan de exploitant het bewijsvermoeden van art. 6:177a lid 1 BW met succes weerleggen? | F4: De exploitant weerlegt het vermoeden alleen dan met succes als hij erin slaagt te bewijzen — waaronder is begrepen voldoende aannemelijk te maken — dat de schade niet is veroorzaakt door de aanleg of de exploitatie van het mijnbouwwerk. | G4: Indien is voldaan aan de vereisten voor toepassing van het vermoeden van art. 6:177a lid 1 BW, weerlegt de exploitant dat vermoeden alleen dan met succes als hij erin slaagt te bewijzen — waaronder is begrepen voldoende aannemelijk te maken — dat de schade niet is veroorzaakt door de aanleg of de exploitatie van het mijnbouwwerk. | H4: Invulling van de bewijslastverdeling: aannemelijk maken volstaat, maar de bewijslast blijft bij de exploitant. | I4: HR 19 juli 2019, ECLI:NL:HR:2019:1278, NJ 2020/391 (Groningenveld)
A5: card_004 | B5: 01 | C5: Groningenveld (HR 19 juli 2019) | D5: arrest | E5: Hoe werkt de persoonlijke predispositie van de benadeelde door in de schadevergoeding bij aansprakelijkheid op grond van art. 6:177 BW? | F5: Schade die (mede) is ontstaan of verergerd door een persoonlijke predispositie moet in beginsel ook op grond van art. 6:98 BW aan de exploitant worden toegerekend. Voor toepassing van art. 6:101 BW (eigen schuld) is slechts onder bijzondere omstandigheden plaats. | G5: Schade door mijnbouwactiviteiten waarvoor de exploitant aansprakelijk is, moet in beginsel ook op grond van art. 6:98 BW aan de exploitant worden toegerekend als deze (mede) is ontstaan of verergerd door een persoonlijke predispositie van de benadeelde. Voor toepassing van art. 6:101 BW is slechts onder bijzondere omstandigheden plaats. | H5: Ruime toerekening: de benadeelde wordt 'genomen zoals hij is' — eggshell-skull-regel ook onder 6:177 BW. | I5: HR 19 juli 2019, ECLI:NL:HR:2019:1278, NJ 2020/391 (Groningenveld)
A6: card_005 | B6: 01 | C6: Groningenveld (HR 19 juli 2019) | D6: arrest | E6: Levert de enkele omstandigheid dat een onroerende zaak niet bestand is tegen bodembeweging een bijzondere kwetsbaarheid op die kan leiden tot vermindering van de schadevergoeding? | F6: Nee. De enkele omstandigheid dat een onroerende zaak niet bestand is tegen bodembeweging vormt geen bijzondere kwetsbaarheid die tot vermindering van de schadevergoeding kan leiden, noch op grond van art. 6:98 BW, noch op grond van art. 6:101 BW. | G6: De enkele omstandigheid dat een onroerende zaak niet bestand is tegen bodembeweging vormt geen bijzondere kwetsbaarheid van die zaak die tot een vermindering van de omvang van de verplichting tot schadevergoeding kan leiden. | H6: Bescherming van eigenaren van oudere/zwakkere bouw in het aardbevingsgebied. | I6: HR 19 juli 2019, ECLI:NL:HR:2019:1278, NJ 2020/391 (Groningenveld)
A7: card_006 | B7: 01 | C7: Groningenveld (HR 19 juli 2019) | D7: leerstuk | E7: Is gederfd woongenot vermogensschade of immateriële schade? | F7: Gederfd woongenot is vermogensschade; daarop kan de bewoner aanspraak maken. De schatting op de voet van art. 6:97 BW gebeurt aan de hand van de door de Hoge Raad in Groningenveld opgestelde richtlijnen. | G7: Indien door (het risico op) bodembeweging het woongenot wordt aangetast, is het daardoor gederfde woongenot vermogensschade op vergoeding waarvan een bewoner aanspraak kan maken. | H7: Onderscheid tussen vermogens- en immateriële schade: aantasting van woongenot is primair vermogensschade. | I7: HR 19 juli 2019, ECLI:NL:HR:2019:1278, NJ 2020/391 (Groningenveld)
A8: card_007 | B8: 01 | C8: Groningenveld (HR 19 juli 2019) | D8: leerstuk | E8: Wanneer kan 'een aantasting in de persoon op andere wijze' ex art. 6:106 onder b BW worden aangenomen zonder dat geestelijk letsel is vastgesteld? | F8: De aard en ernst van de normschending en haar gevolgen kunnen meebrengen dat de aantasting in de persoon zó voor de hand ligt, dat die kan worden aangenomen zonder dat geestelijk letsel naar objectieve maatstaven vaststaat. Enkel schending van een fundamenteel recht is niet voldoende. | G8: Van een aantasting in de persoon op andere wijze als bedoeld in art. 6:106 lid 1, onder b, BW, is niet reeds sprake bij de enkele schending van een fundamenteel recht. | H8: Verfijning van de EBI-lijn (HR 15 maart 2019): strenge maatstaf voor immateriële schade zonder vastgesteld letsel. | I8: HR 19 juli 2019, ECLI:NL:HR:2019:1278, NJ 2020/391 (Groningenveld)
A9: card_008 | B9: 01 | C9: Groningenveld (HR 19 juli 2019) | D9: leerstuk | E9: Staat de formele rechtskracht van instemmingsbesluiten met winningsplannen in de weg aan aansprakelijkheid van de Staat voor aardbevingsschade? | F9: Nee. De formele rechtskracht van instemmingsbesluiten in zaken als de onderhavige staat niet in de weg aan aansprakelijkheid van de Staat, omdat de besluiten niet de vraag regelen of de Staat in een andere hoedanigheid (bv. als medebelanghebbende via EBN) onrechtmatig heeft gehandeld. | G9: De formele rechtskracht van instemmingsbesluiten in zaken als de onderhavige staat niet in de weg aan aansprakelijkheid van de Staat. | H9: Belangrijke nuancering van de leer van de formele rechtskracht bij besluiten met schadeveroorzakende effecten. | I9: HR 19 juli 2019, ECLI:NL:HR:2019:1278, NJ 2020/391 (Groningenveld)
A10: card_009 | B10: 01 | C10: Vivat/ATF (HR 10 januari 2020) | D10: arrest | E10: Wanneer is de omkeringsregel van toepassing bij schending van een veiligheidsnorm die een specifiek gevaar wil voorkomen? | F10: Als een norm specifiek strekt ter bescherming tegen een bepaald gevaar en dat gevaar zich heeft verwezenlijkt, moet de rechter bij onzekerheid over het condicio-sine-qua-non-verband tussen normschending en schade de omkeringsregel toepassen. | G10: Deze norm strekt specifiek ertoe bescherming te bieden tegen het gevaar van een interne ontploffing. Dat gevaar heeft zich verwezenlijkt. Bij die stand van zaken had het hof, als er nog onzekerheid bestond over het condicio sine qua non-verband tussen de schending van de norm en de schade, de omkeringsregel dienen toe te passen. | H10: Casus over soldeermachine die niet afgeschermd was tegen brandbare dampen. Producent aansprakelijk gesteld door verzekeraar Vivat/Reaal. | I10: HR 10 januari 2020, ECLI:NL:HR:2020:47, NJ 2020/45 (Vivat/ATF)
A11: card_010 | B11: 01 | C11: Afzinkkelder (HR 12 januari 2024) | D11: arrest | E11: Hoe beoordeelt de Hoge Raad de aansprakelijkheid van een opdrachtnemer bij bouwwerkzaamheden die schade aan het belendend perceel veroorzaken? | F11: De opdrachtnemer moet bij werkzaamheden die door hun aard risico op schade aan belendende percelen meebrengen (zoals het afzinken van een kelder) grote zorgvuldigheid betrachten en onderzoeken welke voorzorgsmaatregelen nodig zijn; een hoge onderzoeks- en waarschuwingsplicht geldt. | G11: Waar dit risico zich vervolgens heeft verwezenlijkt, kan niet zonder meer worden aanvaard dat [eiseressen] de daardoor veroorzaakte schade dienen te dragen. Hierbij is van belang dat de werkzaamheden in het belang van (de opdrachtgever van) Multi werden uitgevoerd en voor [eiseressen] geen voordeel opleverden, dat de schade van [eiseressen] niet zonder meer behoort tot hetgeen door een derde in het maatschappelijk verkeer moet worden geduld bij bouwwerkzaamheden van een ander, en dat het veeleer op de weg van Multi lag om zich tegen aansprakelijkheid voor het toebrengen van schade aan derden te verzekeren. | H11: HR rov. 3.2.2-3.2.3; letterlijke passage uit de uitspraak, opgenomen in syllabus module 1 (Van Dam), p. 42. | I11: HR 12 januari 2024, ECLI:NL:HR:2024:17 (Afzinkkelder)
A12: card_011 | B12: 01 | C12: MD/Shell (Hof Den Haag 12 november 2024) | D12: arrest | E12: Kan de burgerlijke rechter Shell verplichten tot een specifieke CO2-reductie van 45% in 2030? | F12: Nee. Het hof oordeelt dat er weliswaar een verplichting op Shell rust om gevaarlijke klimaatverandering tegen te gaan, maar de burgerlijke rechter kan niet vaststellen dat Shell haar CO2-emissies met 45% (of enig ander percentage) moet verminderen. | G12: Het hof heeft aan de hand van objectieve aanknopingspunten vastgesteld dat er een verplichting op Shell rust om gevaarlijke klimaatverandering tegen te gaan. Dit betekent echter niet dat de burgerlijke rechter kan vaststellen dat Shell haar CO2-emissies met 45% moet verminderen. | H12: Appel van Urgenda/Shell-lijn: wel zorgplicht, niet concreet reductiepercentage. Klimaataansprakelijkheid van private ondernemingen. | I12: Hof Den Haag 12 november 2024, ECLI:NL:GHDHA:2024:2099 (Milieudefensie/Shell)
A13: card_012 | B13: 01 | C13: MD/Shell (Hof Den Haag 12 november 2024) | D13: arrest | E13: Wat kan meer van Shell worden verwacht dan van andere ondernemingen als het gaat om klimaatverandering? | F13: Van Shell kan meer worden verwacht dan van de meeste andere ondernemingen, gelet op haar omvang als oliemaatschappij en haar bijdrage aan wereldwijde broeikasgasemissies; dat vertaalt zich in een zwaardere zorgplicht, maar niet in een rechterlijk gebod tot een specifiek reductiepercentage. | G13: Van Shell kan meer worden verwacht dan van de meeste andere ondernemingen […] als het gaat om het tegengaan van gevaarlijke klimaatverandering. | H13: Gradueel gedifferentieerde zorgplicht op basis van marktpositie en CO2-bijdrage van de onderneming. | I13: Hof Den Haag 12 november 2024, ECLI:NL:GHDHA:2024:2099 (Milieudefensie/Shell)
... A188: card_187 | B188: 19 | C188: Casus Sadiku/Groen - vraag 3 | D188: casus | E188: Sadiku koopt 4 juni 2019 een houten bedrijfspand met 4-jaarsgarantie tegen ongedierte en een contractuele klachttermijn van 2 maanden. Sadiku constateert termieten op 16 augustus 2019, klaagt op 20 november 2019, procedeert op 5 december 2022. Kan Groen zich op verval en/of verjaring beroepen? | F188: (1) Vervaltermijn van 2 maanden (contractueel): overschreden. Constatering 16 augustus 2019 → uiterste klachtdatum 16 oktober 2019. Klacht op 20 november 2019 is te laat; het recht is op grond van de contractuele klachttermijn vervallen. Enige tempering is mogelijk via art. 6:2 BW (redelijkheid en billijkheid) als het beroep op verval naar maatstaven van r&b onaanvaardbaar is, bijvoorbeeld bij nadeel aan de zijde van Groen (vgl. HR 8 februari 2013, Van de Steeg/Rabobank). Aparte vraag: kwalificeert de 2-maanden-termijn als verval- of als klachttermijn (art. 6:89 BW)? Het beoogde effect (verval van recht) wijst op verval. (2) Verjaring: art. 3:307 (boete/nakoming) en art. 3:310 lid 1 BW (schadevordering) = 5 jaar. Constatering 16 augustus 2019 → verjaart 16 augustus 2024. Procedure 5 december 2022 valt binnen die termijn. Dus verjaring niet; verval wel. | G188: Een schuldeiser kan op een gebrek in de prestatie geen beroep meer doen, indien hij niet binnen bekwame tijd nadat hij het gebrek heeft ontdekt of redelijkerwijs had moeten ontdekken, bij de schuldenaar heeft geprotesteerd. | H188: Huiswerkcasus 3 Dempsey 2026. Focus: onderscheid verval vs. verjaring (card_178); art. 6:89 BW (card_177); art. 3:310 BW (card_168). | I188: Huiswerkopdracht Dempsey 2026, casus 3 vraag 3

Sheet Samenvatting
A1: Overzicht review
A3: Totaal aantal kaarten | B3: =COUNTA('Kaarten review'!A2:A188)
A4: Kaarten module 01 | B4: =COUNTIFS('Kaarten review'!B2:B188,"01")
A5: Kaarten module 02 | B5: =COUNTIFS('Kaarten review'!B2:B188,"02")
A6: Kaarten module 04 | B6: =COUNTIFS('Kaarten review'!B2:B188,"04")
A7: Kaarten module 05 | B7: =COUNTIFS('Kaarten review'!B2:B188,"05")
A8: Kaarten module 06 | B8: =COUNTIFS('Kaarten review'!B2:B188,"06")
A9: Kaarten module 07 | B9: =COUNTIFS('Kaarten review'!B2:B188,"07")
A10: Kaarten module 08 | B10: =COUNTIFS('Kaarten review'!B2:B188,"08")
A11: Kaarten module 11 | B11: =COUNTIFS('Kaarten review'!B2:B188,"11")
A12: Kaarten module 19 | B12: =COUNTIFS('Kaarten review'!B2:B188,"19")
A14: Oordeel: behouden | B14: =COUNTIF('Kaarten review'!J2:J188,"behouden")
A15: Oordeel: aanpassen | B15: =COUNTIF('Kaarten review'!J2:J188,"aanpassen")
A16: Oordeel: verwijderen | B16: =COUNTIF('Kaarten review'!J2:J188,"verwijderen")
A17: Oordeel nog leeg | B17: =COUNTBLANK('Kaarten review'!J2:J188)
A19: Module 01 - behouden | B19: =COUNTIFS('Kaarten review'!B2:B188,"01",'Kaarten review'!J2:J188,"behouden")
A20: Module 01 - aanpassen | B20: =COUNTIFS('Kaarten review'!B2:B188,"01",'Kaarten review'!J2:J188,"aanpassen")
A21: Module 01 - verwijderen | B21: =COUNTIFS('Kaarten review'!B2:B188,"01",'Kaarten review'!J2:J188,"verwijderen")
A23: Module 02 - behouden | B23: =COUNTIFS('Kaarten review'!B2:B188,"02",'Kaarten review'!J2:J188,"behouden")
A24: Module 02 - aanpassen | B24: =COUNTIFS('Kaarten review'!B2:B188,"02",'Kaarten review'!J2:J188,"aanpassen")
A25: Module 02 - verwijderen | B25: =COUNTIFS('Kaarten review'!B2:B188,"02",'Kaarten review'!J2:J188,"verwijderen")
A27: Module 04 - behouden | B27: =COUNTIFS('Kaarten review'!B2:B188,"04",'Kaarten review'!J2:J188,"behouden")
A28: Module 04 - aanpassen | B28: =COUNTIFS('Kaarten review'!B2:B188,"04",'Kaarten review'!J2:J188,"aanpassen")
A29: Module 04 - verwijderen | B29: =COUNTIFS('Kaarten review'!B2:B188,"04",'Kaarten review'!J2:J188,"verwijderen")
A31: Module 05 - behouden | B31: =COUNTIFS('Kaarten review'!B2:B188,"05",'Kaarten review'!J2:J188,"behouden")
A32: Module 05 - aanpassen | B32: =COUNTIFS('Kaarten review'!B2:B188,"05",'Kaarten review'!J2:J188,"aanpassen")
A33: Module 05 - verwijderen | B33: =COUNTIFS('Kaarten review'!B2:B188,"05",'Kaarten review'!J2:J188,"verwijderen")
A35: Module 06 - behouden | B35: =COUNTIFS('Kaarten review'!B2:B188,"06",'Kaarten review'!J2:J188,"behouden")
A36: Module 06 - aanpassen | B36: =COUNTIFS('Kaarten review'!B2:B188,"06",'Kaarten review'!J2:J188,"aanpassen")
A37: Module 06 - verwijderen | B37: =COUNTIFS('Kaarten review'!B2:B188,"06",'Kaarten review'!J2:J188,"verwijderen")
A39: Module 07 - behouden | B39: =COUNTIFS('Kaarten review'!B2:B188,"07",'Kaarten review'!J2:J188,"behouden")
A40: Module 07 - aanpassen | B40: =COUNTIFS('Kaarten review'!B2:B188,"07",'Kaarten review'!J2:J188,"aanpassen")
A41: Module 07 - verwijderen | B41: =COUNTIFS('Kaarten review'!B2:B188,"07",'Kaarten review'!J2:J188,"verwijderen")
A43: Module 08 - behouden | B43: =COUNTIFS('Kaarten review'!B2:B188,"08",'Kaarten review'!J2:J188,"behouden")
A44: Module 08 - aanpassen | B44: =COUNTIFS('Kaarten review'!B2:B188,"08",'Kaarten review'!J2:J188,"aanpassen")
A45: Module 08 - verwijderen | B45: =COUNTIFS('Kaarten review'!B2:B188,"08",'Kaarten review'!J2:J188,"verwijderen")
A47: Module 11 - behouden | B47: =COUNTIFS('Kaarten review'!B2:B188,"11",'Kaarten review'!J2:J188,"behouden")
A48: Module 11 - aanpassen | B48: =COUNTIFS('Kaarten review'!B2:B188,"11",'Kaarten review'!J2:J188,"aanpassen")
A49: Module 11 - verwijderen | B49: =COUNTIFS('Kaarten review'!B2:B188,"11",'Kaarten review'!J2:J188,"verwijderen")
A51: Module 19 - behouden | B51: =COUNTIFS('Kaarten review'!B2:B188,"19",'Kaarten review'!J2:J188,"behouden")
...
